<?xml version="1.0"?>
<robot name="inspection_robot">

  <!-- Base Link -->
  <link name="base_link">
    <visual>
      <origin xyz="0 0 0.05" rpy="0 0 0"/>
      <geometry>
        <cylinder radius="0.3" length="0.1"/>
      </geometry>
      <material name="blue">
        <color rgba="0.2 0.4 0.8 1.0"/>
      </material>
    </visual>
    <collision>
      <origin xyz="0 0 0.05" rpy="0 0 0"/>
      <geometry>
        <cylinder radius="0.3" length="0.1"/>
      </geometry>
    </collision>
    <inertial>
      <mass value="10.0"/>
      <origin xyz="0 0 0.05"/>
      <inertia ixx="0.1" ixy="0" ixz="0" iyy="0.1" iyz="0" izz="0.1"/>
    </inertial>
  </link>

  <!-- Body Link -->
  <link name="body_link">
    <visual>
      <origin xyz="0 0 0.15" rpy="0 0 0"/>
      <geometry>
        <cylinder radius="0.25" length="0.2"/>
      </geometry>
      <material name="gray">
        <color rgba="0.5 0.5 0.5 1.0"/>
      </material>
    </visual>
    <collision>
      <origin xyz="0 0 0.15" rpy="0 0 0"/>
      <geometry>
        <cylinder radius="0.25" length="0.2"/>
      </geometry>
    </collision>
    <inertial>
      <mass value="5.0"/>
      <origin xyz="0 0 0.15"/>
      <inertia ixx="0.05" ixy="0" ixz="0" iyy="0.05" iyz="0" izz="0.05"/>
    </inertial>
  </link>

  <!-- Lidar Link -->
  <link name="lidar_link">
    <visual>
      <origin xyz="0 0 0" rpy="0 0 0"/>
      <geometry>
        <cylinder radius="0.05" length="0.08"/>
      </geometry>
      <material name="black">
        <color rgba="0.1 0.1 0.1 1.0"/>
      </material>
    </visual>
    <collision>
      <geometry>
        <cylinder radius="0.05" length="0.08"/>
      </geometry>
    </collision>
    <inertial>
      <mass value="0.5"/>
      <inertia ixx="0.001" ixy="0" ixz="0" iyy="0.001" iyz="0" izz="0.001"/>
    </inertial>
  </link>

  <!-- IMU Link -->
  <link name="imu_link">
    <visual>
      <origin xyz="0 0 0" rpy="0 0 0"/>
      <geometry>
        <box size="0.03 0.03 0.015"/>
      </geometry>
      <material name="red">
        <color rgba="1.0 0.1 0.1 1.0"/>
      </material>
    </visual>
    <inertial>
      <mass value="0.01"/>
      <inertia ixx="0.0001" ixy="0" ixz="0" iyy="0.0001" iyz="0" izz="0.0001"/>
    </inertial>
  </link>

  <!-- Camera Link -->
  <link name="camera_link">
    <visual>
      <origin xyz="0 0 0" rpy="0 0 0"/>
      <geometry>
        <box size="0.04 0.08 0.03"/>
      </geometry>
      <material name="darkblue">
        <color rgba="0.1 0.1 0.4 1.0"/>
      </material>
    </visual>
    <inertial>
      <mass value="0.1"/>
      <inertia ixx="0.0001" ixy="0" ixz="0" iyy="0.0001" iyz="0" izz="0.0001"/>
    </inertial>
  </link>

  <!-- Wheel Links -->
  <link name="wheel_front_left">
    <visual>
      <origin xyz="0 0 0" rpy="1.5708 0 0"/>
      <geometry>
        <cylinder radius="0.08" length="0.05"/>
      </geometry>
      <material name="black">
        <color rgba="0.2 0.2 0.2 1.0"/>
      </material>
    </visual>
    <collision>
      <origin xyz="0 0 0" rpy="1.5708 0 0"/>
      <geometry>
        <cylinder radius="0.08" length="0.05"/>
      </geometry>
    </collision>
    <inertial>
      <mass value="1.0"/>
      <inertia ixx="0.001" ixy="0" ixz="0" iyy="0.001" iyz="0" izz="0.001"/>
    </inertial>
  </link>

  <link name="wheel_front_right">
    <visual>
      <origin xyz="0 0 0" rpy="1.5708 0 0"/>
      <geometry>
        <cylinder radius="0.08" length="0.05"/>
      </geometry>
      <material name="black">
        <color rgba="0.2 0.2 0.2 1.0"/>
      </material>
    </visual>
    <collision>
      <origin xyz="0 0 0" rpy="1.5708 0 0"/>
      <geometry>
        <cylinder radius="0.08" length="0.05"/>
      </geometry>
    </collision>
    <inertial>
      <mass value="1.0"/>
      <inertia ixx="0.001" ixy="0" ixz="0" iyy="0.001" iyz="0" izz="0.001"/>
    </inertial>
  </link>

  <link name="wheel_back_left">
    <visual>
      <origin xyz="0 0 0" rpy="1.5708 0 0"/>
      <geometry>
        <cylinder radius="0.08" length="0.05"/>
      </geometry>
      <material name="black">
        <color rgba="0.2 0.2 0.2 1.0"/>
      </material>
    </visual>
    <collision>
      <origin xyz="0 0 0" rpy="1.5708 0 0"/>
      <geometry>
        <cylinder radius="0.08" length="0.05"/>
      </geometry>
    </collision>
    <inertial>
      <mass value="1.0"/>
      <inertia ixx="0.001" ixy="0" ixz="0" iyy="0.001" iyz="0" izz="0.001"/>
    </inertial>
  </link>

  <link name="wheel_back_right">
    <visual>
      <origin xyz="0 0 0" rpy="1.5708 0 0"/>
      <geometry>
        <cylinder radius="0.08" length="0.05"/>
      </geometry>
      <material name="black">
        <color rgba="0.2 0.2 0.2 1.0"/>
      </material>
    </visual>
    <collision>
      <origin xyz="0 0 0" rpy="1.5708 0 0"/>
      <geometry>
        <cylinder radius="0.08" length="0.05"/>
      </geometry>
    </collision>
    <inertial>
      <mass value="1.0"/>
      <inertia ixx="0.001" ixy="0" ixz="0" iyy="0.001" iyz="0" izz="0.001"/>
    </inertial>
  </link>

  <!-- Joints -->
  <joint name="base_to_body" type="fixed">
    <parent link="base_link"/>
    <child link="body_link"/>
    <origin xyz="0 0 0.05" rpy="0 0 0"/>
  </joint>

  <joint name="body_to_lidar" type="fixed">
    <parent link="body_link"/>
    <child link="lidar_link"/>
    <origin xyz="0 0 0.25" rpy="0 0 0"/>
  </joint>

  <joint name="body_to_imu" type="fixed">
    <parent link="body_link"/>
    <child link="imu_link"/>
    <origin xyz="0 0 0.2" rpy="0 0 0"/>
  </joint>

  <joint name="body_to_camera" type="fixed">
    <parent link="body_link"/>
    <child link="camera_link"/>
    <origin xyz="0.15 0 0.1" rpy="0 0 0"/>
  </joint>

  <!-- Wheel joints -->
  <joint name="base_to_wfl" type="continuous">
    <parent link="base_link"/>
    <child link="wheel_front_left"/>
    <origin xyz="0.2 0.25 -0.05" rpy="0 0 0"/>
    <axis xyz="0 1 0"/>
  </joint>

  <joint name="base_to_wfr" type="continuous">
    <parent link="base_link"/>
    <child link="wheel_front_right"/>
    <origin xyz="0.2 -0.25 -0.05" rpy="0 0 0"/>
    <axis xyz="0 1 0"/>
  </joint>

  <joint name="base_to_wbl" type="continuous">
    <parent link="base_link"/>
    <child link="wheel_back_left"/>
    <origin xyz="-0.2 0.25 -0.05" rpy="0 0 0"/>
    <axis xyz="0 1 0"/>
  </joint>

  <joint name="base_to_wbr" type="continuous">
    <parent link="base_link"/>
    <child link="wheel_back_right"/>
    <origin xyz="-0.2 -0.25 -0.05" rpy="0 0 0"/>
    <axis xyz="0 1 0"/>
  </joint>

  <!-- Gazebo plugins -->
  <gazebo reference="lidar_link">
    <sensor type="ray" name="lidar_sensor">
      <pose>0 0 0 0 0 0</pose>
      <visualize>true</visualize>
      <update_rate>10</update_rate>
      <ray>
        <scan>
          <horizontal>
            <samples>360</samples>
            <resolution>1</resolution>
            <min_angle>-3.14159</min_angle>
            <max_angle>3.14159</max_angle>
          </horizontal>
        </scan>
        <range>
          <min>0.1</min>
          <max>30</max>
          <resolution>0.01</resolution>
        </range>
        <noise>
          <type>gaussian</type>
          <mean>0.0</mean>
          <stddev>0.01</stddev>
        </noise>
      </ray>
      <plugin name="gazebo_ros_laser" filename="libgazebo_ros_ray_sensor.so">
        <ros>
          <namespace>/robot</namespace>
          <remapping>~/out:=scan</remapping>
        </ros>
        <output_type>sensor_msgs/LaserScan</output_type>
      </plugin>
    </sensor>
  </gazebo>

  <gazebo reference="imu_link">
    <sensor type="imu" name="imu_sensor">
      <always_on>1</always_on>
      <update_rate>100</update_rate>
      <plugin name="gazebo_ros_imu" filename="libgazebo_ros_imu_sensor.so">
        <ros>
          <namespace>/robot</namespace>
          <remapping>~/out:=imu</remapping>
        </ros>
        <frame_name>imu_link</frame_name>
      </plugin>
    </sensor>
  </gazebo>

  <!-- Differential drive plugin -->
  <gazebo>
    <plugin name="gazebo_ros_diff_drive" filename="libgazebo_ros_diff_drive.so">
      <ros>
        <namespace>/robot</namespace>
      </ros>
      <update_rate>50</update_rate>
      <left_joint>base_to_wfl</left_joint>
      <right_joint>base_to_wfr</right_joint>
      <wheel_separation>0.5</wheel_separation>
      <wheel_diameter>0.16</wheel_diameter>
      <max_wheel_torque>20</max_wheel_torque>
      <max_wheel_acceleration>1.0</max_wheel_acceleration>
      <command_topic>cmd_vel</command_topic>
      <publish_wheel_tf>true</publish_wheel_tf>
      <publish_tf>true</publish_tf>
      <odometry_topic>odom</odometry_topic>
      <odometry_frame>odom</odometry_frame>
      <robot_base_frame>base_link</robot_base_frame>
    </plugin>
  </gazebo>

</robot>
