<?xml version="1.0"?>
<robot xmlns:xacro="http://www.ros.org/wiki/xacro"
        xmlns:gazebo="http://gazebosim.org">

  <!-- 属性定义 -->
  <xacro:property name="pi" value="3.1415926535897931"/>
  
  <xacro:property name="base_length" value="0.6"/>
  <xacro:property name="base_width" value="0.5"/>
  <xacro:property name="base_height" value="0.3"/>
  <xacro:property name="base_mass" value="25.0"/>

  <xacro:property name="wheel_radius" value="0.1"/>
  <xacro:property name="wheel_width" value="0.05"/>
  <xacro:property name="wheel_mass" value="1.0"/>
  <xacro:property name="wheel_ygap" value="0.025"/>
  <xacro:property name="wheel_xoff" value="0.2"/>
  <xacro:property name="wheel_zoff" value="0.05"/>

  <!-- 底盘 -->
  <xacro:macro name="robot_base" params="prefix">
    <!-- 底盘主体 -->
    <link name="${prefix}base_link">
      <visual>
        <origin xyz="0 0 ${base_height/2}" rpy="0 0 0"/>
        <geometry>
          <box size="${base_length} ${base_width} ${base_height}"/>
        </geometry>
        <material name="blue">
          <color rgba="0.2 0.4 0.8 1"/>
        </material>
      </visual>
      <collision>
        <origin xyz="0 0 ${base_height/2}" rpy="0 0 0"/>
        <geometry>
          <box size="${base_length} ${base_width} ${base_height}"/>
        </geometry>
      </collision>
      <inertial>
        <origin xyz="0 0 ${base_height/2}" rpy="0 0 0"/>
        <mass value="${base_mass}"/>
        <inertia ixx="${base_mass*(base_width**2 + base_height**2)/12}"
                 iyy="${base_mass*(base_length**2 + base_height**2)/12}"
                 izz="${base_mass*(base_length**2 + base_width**2)/12}"
                 ixy="0" ixz="0" iyz="0"/>
      </inertial>
    </link>

    <!-- 左轮 -->
    <link name="${prefix}left_wheel">
      <visual>
        <origin xyz="0 0 0" rpy="${pi/2} 0 0"/>
        <geometry>
          <cylinder radius="${wheel_radius}" length="${wheel_width}"/>
        </geometry>
        <material name="black">
          <color rgba="0.1 0.1 0.1 1"/>
        </material>
      </visual>
      <collision>
        <origin xyz="0 0 0" rpy="${pi/2} 0 0"/>
        <geometry>
          <cylinder radius="${wheel_radius}" length="${wheel_width}"/>
        </geometry>
      </collision>
      <inertial>
        <mass value="${wheel_mass}"/>
        <inertia ixx="${wheel_mass*(3*wheel_radius**2 + wheel_width**2)/12}"
                 iyy="${wheel_mass*(3*wheel_radius**2 + wheel_width**2)/12}"
                 izz="${wheel_mass*wheel_radius**2/2}"
                 ixy="0" ixz="0" iyz="0"/>
      </inertial>
    </link>

    <joint name="${prefix}left_wheel_joint" type="continuous">
      <parent link="${prefix}base_link"/>
      <child link="${prefix}left_wheel"/>
      <origin xyz="${wheel_xoff} ${base_width/2 + wheel_ygap} ${-wheel_zoff}" rpy="0 0 0"/>
      <axis xyz="0 1 0"/>
    </joint>

    <!-- 右轮 -->
    <link name="${prefix}right_wheel">
      <visual>
        <origin xyz="0 0 0" rpy="${pi/2} 0 0"/>
        <geometry>
          <cylinder radius="${wheel_radius}" length="${wheel_width}"/>
        </geometry>
        <material name="black">
          <color rgba="0.1 0.1 0.1 1"/>
        </material>
      </visual>
      <collision>
        <origin xyz="0 0 0" rpy="${pi/2} 0 0"/>
        <geometry>
          <cylinder radius="${wheel_radius}" length="${wheel_width}"/>
        </geometry>
      </collision>
      <inertial>
        <mass value="${wheel_mass}"/>
        <inertia ixx="${wheel_mass*(3*wheel_radius**2 + wheel_width**2)/12}"
                 iyy="${wheel_mass*(3*wheel_radius**2 + wheel_width**2)/12}"
                 izz="${wheel_mass*wheel_radius**2/2}"
                 ixy="0" ixz="0" iyz="0"/>
      </inertial>
    </link>

    <joint name="${prefix}right_wheel_joint" type="continuous">
      <parent link="${prefix}base_link"/>
      <child link="${prefix}right_wheel"/>
      <origin xyz="${wheel_xoff} ${-(base_width/2 + wheel_ygap)} ${-wheel_zoff}" rpy="0 0 0"/>
      <axis xyz="0 1 0"/>
    </joint>

    <!-- 激光雷达 -->
    <link name="${prefix}lidar_link">
      <visual>
        <origin xyz="0 0 0" rpy="0 0 0"/>
        <geometry>
          <cylinder radius="0.05" length="0.05"/>
        </geometry>
        <material name="darkgray">
          <color rgba="0.2 0.2 0.2 1"/>
        </material>
      </visual>
      <collision>
        <geometry>
          <cylinder radius="0.05" length="0.05"/>
        </geometry>
      </collision>
      <inertial>
        <mass value="0.1"/>
        <inertia ixx="0.0001" ixy="0" ixz="0" iyy="0.0001" iyz="0" izz="0.0001"/>
      </inertial>
    </link>

    <joint name="${prefix}lidar_joint" type="fixed">
      <parent link="${prefix}base_link"/>
      <child link="${prefix}lidar_link"/>
      <origin xyz="0 0 ${base_height + 0.025}" rpy="0 0 0"/>
    </joint>

    <!-- IMU -->
    <link name="${prefix}imu_link">
      <visual>
        <origin xyz="0 0 0" rpy="0 0 0"/>
        <geometry>
          <box size="0.03 0.03 0.015"/>
        </geometry>
        <material name="red">
          <color rgba="1 0.1 0.1 1"/>
        </material>
      </visual>
      <inertial>
        <mass value="0.01"/>
        <inertia ixx="0.0001" ixy="0" ixz="0" iyy="0.0001" iyz="0" izz="0.0001"/>
      </inertial>
    </link>

    <joint name="${prefix}imu_joint" type="fixed">
      <parent link="${prefix}base_link"/>
      <child link="${prefix}imu_link"/>
      <origin xyz="0 0 ${base_height/2}" rpy="0 0 0"/>
    </joint>

    <!-- Gazebo 插件 -->
    <gazebo reference="${prefix}lidar_link">
      <sensor type="ray" name="lidar_sensor">
        <pose>0 0 0 0 0 0</pose>
        <visualize>true</visualize>
        <update_rate>10</update_rate>
        <ray>
          <scan>
            <horizontal>
              <samples>360</samples>
              <resolution>1</resolution>
              <min_angle>-3.14159</min_angle>
              <max_angle>3.14159</max_angle>
            </horizontal>
          </scan>
          <range>
            <min>0.1</min>
            <max>30</max>
            <resolution>0.01</resolution>
          </range>
        </ray>
        <plugin name="gazebo_ros_laser" filename="libgazebo_ros_ray_sensor.so">
          <ros>
            <namespace>/robot</namespace>
            <remapping>~/out:=scan</remapping>
          </ros>
          <output_type>sensor_msgs/LaserScan</output_type>
        </plugin>
      </sensor>
    </gazebo>

    <gazebo reference="${prefix}imu_link">
      <sensor type="imu" name="imu_sensor">
        <always_on>1</always_on>
        <update_rate>100</update_rate>
        <plugin name="gazebo_ros_imu" filename="libgazebo_ros_imu_sensor.so">
          <ros>
            <namespace>/robot</namespace>
            <remapping>~/out:=imu</remapping>
          </ros>
          <frame_name>imu_link</frame_name>
        </plugin>
      </sensor>
    </gazebo>

    <!-- 差速驱动插件 -->
    <gazebo>
      <plugin name="gazebo_ros_diff_drive" filename="libgazebo_ros_diff_drive.so">
        <ros>
          <namespace>/robot</namespace>
        </ros>
        <update_rate>50</update_rate>
        <left_joint>${prefix}left_wheel_joint</left_joint>
        <right_joint>${prefix}right_wheel_joint</right_joint>
        <wheel_separation>${base_width + 2*wheel_ygap}</wheel_separation>
        <wheel_diameter>${2*wheel_radius}</wheel_diameter>
        <max_wheel_torque>20</max_wheel_torque>
        <max_wheel_acceleration>1.0</max_wheel_acceleration>
        <command_topic>cmd_vel</command_topic>
        <publish_wheel_tf>true</publish_wheel_tf>
        <publish_tf>true</publish_tf>
        <odometry_topic>odom</odometry_topic>
        <odometry_frame>odom</odometry_frame>
        <robot_base_frame>${prefix}base_link</robot_base_frame>
      </plugin>
    </gazebo>

  </xacro:macro>

</robot>
